### 导读

前端开发中，许多开发者不是很重视关于异常捕获的使用，但是异常捕获是程序可靠性的重要保证之一，你肯定也不希望你的程序在执行了某个操作之后就崩溃了吧！所以掌握异常捕获还是十分有必要的。本篇文章首先会简单介绍异常捕获的基本语法以及用法，然后再深入解析在异步情况下异常捕获的行为状态和使用方法。

### 基本内容

#### 基本语法

~~~js
try{
	// 正常执行代码
}catch(err){
	// 错误抛出处理代码
}
finally{
	// 必然执行的代码
}
~~~

#### 错误抛出

~~~js
// throw关键字是用于抛出错误的
// 它的参数可以是任意类型
// 但最好是对象
throw 'any string'; // 没问题
throw new Error('err') // 符合规范的语法
~~~

#### 全局catch

我们可能遇到error没有被try...catch...捕获的情况，这样我们的程序很可能会停止，但是我们又无法保证所有error都能被try...catch...捕获，所以我们可以通过下面的语法进行全局错误捕获：

~~~js
window.onerror = ()=>{

}
~~~

#### 注意点

`try...catch` **仅对运行时的 error 有效**

如果try中的代码不是能够正常执行的`javascript`代码，那么try是无法捕获到错误的，比如：

~~~js
try {
  {{{{{{{{{{{{
} catch (err) {
  alert("引擎无法理解这段代码，它是无效的");
}
~~~

`try...catch` **同步执行**

这个是本篇文章的核心，不过在本小节只是举一个现象：

~~~js
try {
  setTimeout(function() {
    noSuchVariable; // 脚本将在这里停止运行
  }, 1000);
} catch (err) {
  alert( "不工作" );
}
~~~

### 异步下的异常捕获

通过前面的内容，我们可以知道try...catch是`同步语法`，其处理不了异步，比如：

~~~js
function A() {
  try {
    Promise.resolve().then(() => {
      throw new Error("any");
    });
  } catch (e) {
    console.log(e.message);
  }
}
A(); // 抛出错误，catch无效
~~~

要如何才捕获到异步内容呢？将其变为同步的：

~~~js
async function A() {
  try {
    await Promise.resolve().then(() => {
      throw new Error("any");
    });
  } catch (e) {
    console.log(e.message);
  }
}
A(); //输出 any
~~~

那像那些无法使用`async`语法的异步函数该如何处理报错呢？比如：

~~~js
try {
  setTimeout(function() {
    noSuchVariable; // 脚本将在这里停止运行
  }, 1000);
} catch (err) {
  alert( "不工作" );
}
~~~

我们可以这样：

~~~js
try {
  setTimeout(function () {
    try {
      noSuchVariable; // 脚本将在这里停止运行
    } catch (err) {
      console.log(err.message);
    }
  }, 1000);
} catch (err) {
  console.log("不工作");
}
~~~

但有的时候，我们希望让外层的try...catch捕获到错误，我们可以这样：

~~~js
try {
  await new Promise((resolve, reject) => {
    setTimeout(function () {
      try {
        noSuchVariable; // 脚本将在这里停止运行
        resolve();
      } catch (err) {
        reject(err);
      }
    }, 1000);
  });
} catch (err) {
  console.log(err.message);
}
~~~

上面都属于浅层的情况，很容易进行同步展开，但是一旦遇到深层嵌套，事情可能就变得复杂了，我们参考下面这个例子：

~~~js
async function A(resolve) {
  await Promise.resolve().then(() => {
    try {
      throw new Error("any");
    } finally {
      resolve();
    }
  });
}
try {
  await new Promise((resolve) => { // await等待的是此Promise，但是我们忽略了A实际上也是一个Promise
    A(resolve);
  });
  console.log("promise执行结束");
} catch (err) {
  console.log(err.message); // 不执行
}
~~~

看到上面的例子，我们可能会想当然的认为try...catch可以捕获到A里抛出的错误，但是实际上却与我们所想大相径庭。其执行结果是这样的:

![](.\images\Snipaste_2025-04-02_10-20-48.jpg)

我们来分析一下上述代码的执行步骤：

1. ![](.\images\Snipaste_2025-04-02_10-10-11.jpg)

2. ![](.\images\Snipaste_2025-04-02_10-11-50.jpg)

3. ![](.\images\Snipaste_2025-04-02_10-14-03.jpg)

4. ![](.\images\Snipaste_2025-04-02_10-15-06.jpg)

5. ![](.\images\Snipaste_2025-04-02_10-44-43.jpg)

   执行到这一步时，有一个非常重要的知识点，大家会不会有一个疑惑，明明error是先被抛出的，为什么先打印的是“promise执行结束”（参考前面的输出图片）？

   这其实是try...catch比较让人迷惑的特性，我们来看一个例子：

   ~~~js
   try {
       throw new Error('any');
   } finally {
       console.log("finally语句");
   }
   // 输出：
   // finally语句
   // Error: any
   ~~~

   可以发现，即使不是异步环境，try...catch也会先把finally的内容先输出，如果finally中存在return，那么错误将被吞噬，不被输出：

   ~~~js
   function test() {
       try {
           throw new Error('any');
       } finally {
           console.log("finally语句");
           return '返回值';
       }
   }
   console.log(test());
   // 输出：
   // finally语句
   // 返回值
   ~~~

   下面是`ECMA`关于try...finally的规范：

   ![](.\images\Snipaste_2025-04-02_10-53-48.jpg)

   名词解释

   - `Evaluation`：调用；

   - `Completion`：判断Block是不是`Completion Record`，是的话将返回值设置为`Completion Record`；
   - `completion Record`：![](.\images\Snipaste_2025-04-02_11-05-03.jpg)
   - `UpdateEmpty`：![](.\images\Snipaste_2025-04-02_11-11-02.jpg)

   这样看下来就可以解决上面的问题了：

   我们看到`ECMA`定义中的B和F作为Completion，可以将其看成一个函数，其返回：

   ~~~js
   {
       type: 'normal|return|...' //normal表示正常执行，return表示有返回值
       value: ... // 执行后的返回值
       target: ...
   }
   ~~~

   `ECMA`的执行语句就可以这样描述：

   ~~~js
   const tryFinally(){
       let B = Completion(tryBlock());
   	let F = Completion(finallyBlock());
   	if(F.type==='normal'){
           return B.value
       }
       return UpdateEmpty(F,undefined);
   }
   ~~~

   - 关于finally中`console.log`打印在try抛出错误之前的问题

     我们可以想象在底层运行时，throw只是一个值对象，等被`tryFinally`return之后，才会作为错误被打印到终端，所以`tryFinally`的执行过程就可以解释这个问题了，F执行时先执行`console.log`输出值，之后才进行错误值的返回，才将错误打印到终端

   - 关于finally中有return后try抛出的错误被覆盖的问题

     这个就很直观，因为有finally有return语句则会走`return UpdateEmpty(F,undefined)`，就会返回F的值，不走`return B.value`，B的错误返回就被覆盖了

   看到这里，可能读者还会有疑惑：resolve()执行后，`promise1`完成了，后面的`console.log("promise执行结束")`也是后面加进来的微任务，也不应该在throw之前执行啊！

   要解决这个疑问我们首先要继承上面的思想，将throw当成一个return语句，而throw的error则作为一个值，在promise内的环境中，如果存在返回值，那么它将作为promise的状态并将状态延续至微任务，也就是说，`throw new Error('any')`进入了微队列之中，借鉴`tryFinally`函数，这个进入的过程可以看出是在`resolve()`之后的，也就是说进行报错的这个微任务是在`promise1`的微任务之后的！这就解释了上面输出的情况，虽然看似简单的输出，实际上暗藏玄机！

6. ![](.\images\Snipaste_2025-04-02_13-39-43.jpg)

以上就是代码的执行过程，然后有的读者可能会认为，将代码像如下修改即可正常捕获了：

~~~js
async function A(resolve) {
  await Promise.resolve().then(() => {
    try {
      throw new Error("any");
    } finally {
      resolve();
    }
  });
}
try {
  await new Promise(async (resolve) => {
    await A(resolve);  // 添加同步等待
  });
  console.log("promise执行结束");
} catch (err) {
  console.log(err.message);
}
~~~

但很遗憾，这样还是捕获不到错误，因为`await A(resolve)`等待的是`promise2`的完成，错误是属于`promise3`的错误，并且在`promise2`中没有任何语句用于捕获或返回该错误，所以该错误并不会被`promise2`抛出，所以即使写成`await A(resolve)`也无法捕获到该错误。

简单的修改方式为：

~~~js
async function A(resolve) {
  try {
    await Promise.resolve().then(() => {
      try {
        throw new Error("any");
      } finally {
        resolve();
      }
    });
  } catch (err) {
    console.log(err.message);
  }
}
try {
  await new Promise((resolve) => {
    A(resolve);
  });
  console.log("promise执行结束");
} catch (err) {
  console.log(err.message);
}
~~~

也就是显式的在`promise2`中进行捕获，但是有的时候我们并不希望在中间层进行错误捕获，因为这样会使我们的编码十分混乱，我们一般希望统一管理错误，那么我们可以这样进行修改：

~~~js
async function A(resolve, reject) {
  await Promise.resolve().then(() => {
    try {
      throw new Error("any");
    } catch (err) {
      reject(err);
    }
  });
}

try {
  await new Promise((resolve, reject) => {
    A(resolve, reject);
  });
  console.log("promise执行结束");
} catch (err) {
  console.log("捕获错误：", err.message);
}
~~~

将顶层的reject传递下去，内层存在错误就通过reject将其返回给顶层。

可能有读者还会异想天开，写出了如下代码：

~~~js
async function A(resolve) {
  throw await Promise.resolve().then(() => {
    try {
      throw new Error("any");
    } finally {
      resolve();
    }
  });
}
try {
  await new Promise(async (resolve) => {
    await A(resolve); // 添加同步等待
  });
  console.log("promise执行结束");
} catch (err) {
  console.log(err.message);
}
~~~

目的是将`promise3`的错误再抛出。但是很遗憾，这种是无法实现再抛出的，我们一般要实现再抛出只能再套一层try...catch，比如：

~~~js
try {
  try {
    throw new Error("any");
  } catch (err) {
    if (err.message === "any") {
      throw new Error("reThrow err:any");
    }
  }
} catch (err) {
  console.log(err.message);
}
~~~

这其实是throw的特性，一旦错误通过throw抛出，只能通过try...catch进行再抛出，throw throw new Error('any')的写法是不合理的。

### 参考文献

[错误处理](https://zh.javascript.info/error-handling)

[ECMA262](https://262.ecma-international.org/)